Workbook
Name GearDB_names: GearDB!$A$2:$A$888
Name GearDB_STR: GearDB!$D$2:$D$888
Name GearDB_DEX: GearDB!$E$2:$E$888
Name GearDB_VIT: GearDB!$F$2:$F$888
Name GearDB_AGI: GearDB!$G$2:$G$888
Name GearDB_INT: GearDB!$H$2:$H$888
Name GearDB_MND: GearDB!$I$2:$I$888
Name GearDB_CHR: GearDB!$J$2:$J$888
Name GearDB_ATT: GearDB!$K$2:$K$888
Name GearDB_ATTP: GearDB!$L$2:$L$888
Name GearDB_ACC: GearDB!$M$2:$M$888
Name GearDB_CRITHITRATE: GearDB!$N$2:$N$888
Name GearDB_CRIT_DMG_INCREASE: GearDB!$O$2:$O$888
Name GearDB_DOUBLE_ATTACK: GearDB!$P$2:$P$888
Name GearDB_TRIPLE_ATTACK: GearDB!$Q$2:$Q$888
Name GearDB_QUAD_ATTACK: GearDB!$R$2:$R$888
Name GearDB_HASTE_GEAR: GearDB!$S$2:$S$888
Name GearDB_HASTE_MAGIC: GearDB!$T$2:$T$888
Name GearDB_HASTE_ABILITY: GearDB!$U$2:$U$888
Name GearDB_DUAL_WIELD: GearDB!$V$2:$V$888
Name GearDB_STORETP: GearDB!$W$2:$W$888
Name GearDB_TP_BONUS: GearDB!$X$2:$X$888
Name GearDB_ALL_WSDMG_ALL_HITS: GearDB!$Y$2:$Y$888
Name GearDB_ALL_WSDMG_FIRST_HIT: GearDB!$Z$2:$Z$888
Name GearDB_ANY_FTP_BONUS: GearDB!$AA$2:$AA$888
Name GearDB_WSACC: GearDB!$AB$2:$AB$888
Name GearDB_WSDMG_225: GearDB!$AC$2:$AC$888
Name AugDB_labels: AugDB!$A$2:$A$40
Name AugDB_STR: AugDB!$C$2:$C$40
Name AugDB_DEX: AugDB!$D$2:$D$40
Name AugDB_VIT: AugDB!$E$2:$E$40
Name AugDB_AGI: AugDB!$F$2:$F$40
Name AugDB_INT: AugDB!$G$2:$G$40
Name AugDB_MND: AugDB!$H$2:$H$40
Name AugDB_CHR: AugDB!$I$2:$I$40
Name AugDB_ATT: AugDB!$J$2:$J$40
Name AugDB_ATTP: AugDB!$K$2:$K$40
Name AugDB_ACC: AugDB!$L$2:$L$40
Name AugDB_CRITHITRATE: AugDB!$M$2:$M$40
Name AugDB_CRIT_DMG_INCREASE: AugDB!$N$2:$N$40
Name AugDB_DOUBLE_ATTACK: AugDB!$O$2:$O$40
Name AugDB_TRIPLE_ATTACK: AugDB!$P$2:$P$40
Name AugDB_QUAD_ATTACK: AugDB!$Q$2:$Q$40
Name AugDB_HASTE_GEAR: AugDB!$R$2:$R$40
Name AugDB_HASTE_MAGIC: AugDB!$S$2:$S$40
Name AugDB_HASTE_ABILITY: AugDB!$T$2:$T$40
Name AugDB_DUAL_WIELD: AugDB!$U$2:$U$40
Name AugDB_STORETP: AugDB!$V$2:$V$40
Name AugDB_TP_BONUS: AugDB!$W$2:$W$40
Name AugDB_ALL_WSDMG_ALL_HITS: AugDB!$X$2:$X$40
Name AugDB_ALL_WSDMG_FIRST_HIT: AugDB!$Y$2:$Y$40
Name AugDB_ANY_FTP_BONUS: AugDB!$Z$2:$Z$40
Name AugDB_WSACC: AugDB!$AA$2:$AA$40
Name AugDB_WSDMG_225: AugDB!$AB$2:$AB$40
Name list_targets: Targets!$A$2:$A$16
Name list_ws: WSDB!$A$2:$A$13
Name list_slot2: Lists!$A$2:$A$11
Name list_slot3: Lists!$B$2:$B$26
Name list_slot4: Lists!$C$2:$C$154
Name list_slot5: Lists!$D$2:$D$152

Sheet Guide
A1: Gear / Augment DPS Optimizer
A3: Built for PLD99/NIN99. Curated gear: 887 items, 39 augments, 12 weaponskills, 15 targets.
A5: HOW TO USE
A6: 1. Go to the Build sheet.
A7: 2. Pick a Target and Weaponskill at the top, and set WS TP.
A8: 3. For each slot, choose an Item from the dropdown:
A9: (keep equipped) = your current piece (with its real augments)
A10: (none) = nothing in that slot
A11: or any curated item the dropdown offers for that slot.
A12: 4. Optionally add an Augment (and Count 1-4 for stacked catalysts),
A13: or type a Free mod + value for an augment not in the catalog.
A14: 5. The Auto/WS/Rotation numbers on the Build sheet update instantly.
... A28: name instead gives its un-augmented base so you can re-augment it.

Sheet Build
A1: Gear / Augment DPS Optimizer
A2: Pick an item + augment per slot. Numbers recompute live. "(keep equipped)" = your current piece.
A4: Target: | B4: Leaping Lizzy
A5: Weaponskill: | B5: chant_du_cygne
A6: WS TP: | B6: 1000
A8: Result | B8: live | C8: engine baseline
A9: Auto-attack DPS | B9: =Calc!$B$145 | C9: 434
A10: WS damage | B10: =Calc!$B$186 | C10: 37068.1
A11: Rotation DPS | B11: =Calc!$B$188 | C11: 2787.4
A12: (baseline = all slots "keep equipped", vs the default target/WS above)
A13: Slot | B13: Item | C13: Augment | D13: Count | E13: Free mod 1 | F13: Val 1 | G13: Free mod 2 | H13: Val 2
A14: range | B14: (keep equipped) | C14: (none) | D14: 1 | E14: (none) | G14: (none)
A15: ammo | B15: (keep equipped) | C15: (none) | D15: 1 | E15: (none) | G15: (none)
A16: head | B16: (keep equipped) | C16: (none) | D16: 1 | E16: (none) | G16: (none)
A17: body | B17: (keep equipped) | C17: (none) | D17: 1 | E17: (none) | G17: (none)
A18: hands | B18: (keep equipped) | C18: (none) | D18: 1 | E18: (none) | G18: (none)
A19: legs | B19: (keep equipped) | C19: (none) | D19: 1 | E19: (none) | G19: (none)
A20: feet | B20: (keep equipped) | C20: (none) | D20: 1 | E20: (none) | G20: (none)
A21: neck | B21: (keep equipped) | C21: (none) | D21: 1 | E21: (none) | G21: (none)
A22: waist | B22: (keep equipped) | C22: (none) | D22: 1 | E22: (none) | G22: (none)
A23: ear1 | B23: (keep equipped) | C23: (none) | D23: 1 | E23: (none) | G23: (none)
A24: ear2 | B24: (keep equipped) | C24: (none) | D24: 1 | E24: (none) | G24: (none)
A25: ring1 | B25: (keep equipped) | C25: (none) | D25: 1 | E25: (none) | G25: (none)
... A27: back | B27: (keep equipped) | C27: (none) | D27: 1 | E27: (none) | G27: (none)

Sheet Stats
A1: Your !mystats anchor
A2: EDIT these to match YOUR /mystats (unbuffed, no food).
A4: STR | B4: 180
A5: DEX | B5: 175
A6: VIT | B6: 210
A7: AGI | B7: 160
A8: INT | B8: 140
A9: MND | B9: 200
A10: CHR | B10: 150
A11: Melee ATT | B11: 1250
A12: Melee ACC | B12: 1180
A13: Wpn dmg | B13: 181
A14: Crit hit rate % | B14: 8
A15: Crit dmg +% | B15: 0
... A26: WS dmg 1st hit % | B26: 0

Sheet GearCalc
A1: slot | B1: itemRow | C1: augRow | D1: STR | E1: DEX | F1: VIT | G1: AGI | H1: INT | I1: MND | J1: CHR | K1: ATT | L1: ATTP | M1: ACC | N1: CRITHITRATE | O1: CRIT_DMG_INCREASE | P1: DOUBLE_ATTACK | Q1: TRIPLE_ATTACK | R1: QUAD_ATTACK | S1: HASTE_GEAR | T1: HASTE_MAGIC | U1: HASTE_ABILITY | V1: DUAL_WIELD | W1: STORETP | X1: TP_BONUS | Y1: ALL_WSDMG_ALL_HITS | Z1: ALL_WSDMG_FIRST_HIT | AA1: ANY_FTP_BONUS | AB1: WSACC | AC1: WSDMG_225
A2: range | B2: =IFERROR(MATCH(Build!$B$14,GearDB_names,0),0) | C2: =IFERROR(MATCH(Build!$C$14,AugDB_labels,0),0) | D2: =IF(Build!$B$14="(keep equipped)",EquipBase!$B$2,IF(OR(Build!$B$14="(none)",Build!$B$14=""),0,IFERROR(INDEX(GearDB_STR,$B$2),0)))+IF(Build!$B$14="(keep equipped)",0,IF($C$2>0,Build!$D$14*INDEX(AugDB_STR,$C$2),0)+IF(Build!$E$14="STR",Build!$F$14,0)+IF(Build!$G$14="STR",Build!$H$14,0)) | E2: =IF(Build!$B$14="(keep equipped)",EquipBase!$C$2,IF(OR(Build!$B$14="(none)",Build!$B$14=""),0,IFERROR(INDEX(GearDB_DEX,$B$2),0)))+IF(Build!$B$14="(keep equipped)",0,IF($C$2>0,Build!$D$14*INDEX(AugDB_DEX,$C$2),0)+IF(Build!$E$14="DEX",Build!$F$14,0)+IF(Build!$G$14="DEX",Build!$H$14,0)) | F2: =IF(Build!$B$14="(keep equipped)",EquipBase!$D$2,IF(OR(Build!$B$14="(none)",Build!$B$14=""),0,IFERROR(INDEX(GearDB_VIT,$B$2),0)))+IF(Build!$B$14="(keep equipped)",0,IF($C$2>0,Build!$D$14*INDEX(AugDB_VIT,$C$2),0)+IF(Build!$E$14="VIT",Build!$F$14,0)+IF(Build!$G$14="VIT",Build!$H$14,0)) | G2: =IF(Build!$B$14="(keep equipped)",EquipBase!$E$2,IF(OR(Build!$B$14="(none)",Build!$B$14=""),0,IFERROR(INDEX(GearDB_AGI,$B$2),0)))+IF(Build!$B$14="(keep equipped)",0,IF($C$2>0,Build!$D$14*INDEX(AugDB_AGI,$C$2),0)+IF(Build!$E$14="AGI",Build!$F$14,0)+IF(Build!$G$14="AGI",Build!$H$14,0)) | H2: =IF(Build!$B$14="(keep equipped)",EquipBase!$F$2,IF(OR(Build!$B$14="(none)",Build!$B$14=""),0,IFERROR(INDEX(GearDB_INT,$B$2),0)))+IF(Build!$B$14="(keep equipped)",0,IF($C$2>0,Build!$D$14*INDEX(AugDB_INT,$C$2),0)+IF(Build!$E$14="INT",Build!$F$14,0)+IF(Build!$G$14="INT",Build!$H$14,0)) | I2: =IF(Build!$B$14="(keep equipped)",EquipBase!$G$2,IF(OR(Build!$B$14="(none)",Build!$B$14=""),0,IFERROR(INDEX(GearDB_MND,$B$2),0)))+IF(Build!$B$14="(keep equipped)",0,IF($C$2>0,Build!$D$14*INDEX(AugDB_MND,$C$2),0)+IF(Build!$E$14="MND",Build!$F$14,0)+IF(Build!$G$14="MND",Build!$H$14,0)) | J2: =IF(Build!$B$14="(keep equipped)",EquipBase!$H$2,IF(OR(Build!$B$14="(none)",Build!$B$14=""),0,IFERROR(INDEX(GearDB_CHR,$B$2),0)))+IF(Build!$B$14="(keep equipped)",0,IF($C$2>0,Build!$D$14*INDEX(AugDB_CHR,$C$2),0)+IF(Build!$E$14="CHR",Build!$F$14,0)+IF(Build!$G$14="CHR",Build!$H$14,0)) | K2: =IF(Build!$B$14="(keep equipped)",EquipBase!$I$2,IF(OR(Build!$B$14="(none)",Build!$B$14=""),0,IFERROR(INDEX(GearDB_ATT,$B$2),0)))+IF(Build!$B$14="(keep equipped)",0,IF($C$2>0,Build!$D$14*INDEX(AugDB_ATT,$C$2),0)+IF(Build!$E$14="ATT",Build!$F$14,0)+IF(Build!$G$14="ATT",Build!$H$14,0)) | L2: =IF(Build!$B$14="(keep equipped)",EquipBase!$J$2,IF(OR(Build!$B$14="(none)",Build!$B$14=""),0,IFERROR(INDEX(GearDB_ATTP,$B$2),0)))+IF(Build!$B$14="(keep equipped)",0,IF($C$2>0,Build!$D$14*INDEX(AugDB_ATTP,$C$2),0)+IF(Build!$E$14="ATTP",Build!$F$14,0)+IF(Build!$G$14="ATTP",Build!$H$14,0)) | M2: =IF(Build!$B$14="(keep equipped)",EquipBase!$K$2,IF(OR(Build!$B$14="(none)",Build!$B$14=""),0,IFERROR(INDEX(GearDB_ACC,$B$2),0)))+IF(Build!$B$14="(keep equipped)",0,IF($C$2>0,Build!$D$14*INDEX(AugDB_ACC,$C$2),0)+IF(Build!$E$14="ACC",Build!$F$14,0)+IF(Build!$G$14="ACC",Build!$H$14,0)) | N2: =IF(Build!$B$14="(keep equipped)",EquipBase!$L$2,IF(OR(Build!$B$14="(none)",Build!$B$14=""),0,IFERROR(INDEX(GearDB_CRITHITRATE,$B$2),0)))+IF(Build!$B$14="(keep equipped)",0,IF($C$2>0,Build!$D$14*INDEX(AugDB_CRITHITRATE,$C$2),0)+IF(Build!$E$14="CRITHITRATE",Build!$F$14,0)+IF(Build!$G$14="CRITHITRATE",Build!$H$14,0)) | O2: =IF(Build!$B$14="(keep equipped)",EquipBase!$M$2,IF(OR(Build!$B$14="(none)",Build!$B$14=""),0,IFERROR(INDEX(GearDB_CRIT_DMG_INCREASE,$B$2),0)))+IF(Build!$B$14="(keep equipped)",0,IF($C$2>0,Build!$D$14*INDEX(AugDB_CRIT_DMG_INCREASE,$C$2),0)+IF(Build!$E$14="CRIT_DMG_INCREASE",Build!$F$14,0)+IF(Build!$G$14="CRIT_DMG_INCREASE",Build!$H$14,0)) | P2: =IF(Build!$B$14="(keep equipped)",EquipBase!$N$2,IF(OR(Build!$B$14="(none)",Build!$B$14=""),0,IFERROR(INDEX(GearDB_DOUBLE_ATTACK,$B$2),0)))+IF(Build!$B$14="(keep equipped)",0,IF($C$2>0,Build!$D$14*INDEX(AugDB_DOUBLE_ATTACK,$C$2),0)+IF(Build!$E$14="DOUBLE_ATTACK",Build!$F$14,0)+IF(Build!$G$14="DOUBLE_ATTACK",Build!$H$14,0)) | Q2: =IF(Build!$B$14="(keep equipped)",EquipBase!$O$2,IF(OR(Build!$B$14="(none)",Build!$B$14=""),0,IFERROR(INDEX(GearDB_TRIPLE_ATTACK,$B$2),0)))+IF(Build!$B$14="(keep equipped)",0,IF($C$2>0,Build!$D$14*INDEX(AugDB_TRIPLE_ATTACK,$C$2),0)+IF(Build!$E$14="TRIPLE_ATTACK",Build!$F$14,0)+IF(Build!$G$14="TRIPLE_ATTACK",Build!$H$14,0)) | R2: =IF(Build!$B$14="(keep equipped)",EquipBase!$P$2,IF(OR(Build!$B$14="(none)",Build!$B$14=""),0,IFERROR(INDEX(GearDB_QUAD_ATTACK,$B$2),0)))+IF(Build!$B$14="(keep equipped)",0,IF($C$2>0,Build!$D$14*INDEX(AugDB_QUAD_ATTACK,$C$2),0)+IF(Build!$E$14="QUAD_ATTACK",Build!$F$14,0)+IF(Build!$G$14="QUAD_ATTACK",Build!$H$14,0)) | S2: =IF(Build!$B$14="(keep equipped)",EquipBase!$Q$2,IF(OR(Build!$B$14="(none)",Build!$B$14=""),0,IFERROR(INDEX(GearDB_HASTE_GEAR,$B$2),0)))+IF(Build!$B$14="(keep equipped)",0,IF($C$2>0,Build!$D$14*INDEX(AugDB_HASTE_GEAR,$C$2),0)+IF(Build!$E$14="HASTE_GEAR",Build!$F$14,0)+IF(Build!$G$14="HASTE_GEAR",Build!$H$14,0)) | T2: =IF(Build!$B$14="(keep equipped)",EquipBase!$R$2,IF(OR(Build!$B$14="(none)",Build!$B$14=""),0,IFERROR(INDEX(GearDB_HASTE_MAGIC,$B$2),0)))+IF(Build!$B$14="(keep equipped)",0,IF($C$2>0,Build!$D$14*INDEX(AugDB_HASTE_MAGIC,$C$2),0)+IF(Build!$E$14="HASTE_MAGIC",Build!$F$14,0)+IF(Build!$G$14="HASTE_MAGIC",Build!$H$14,0)) | U2: =IF(Build!$B$14="(keep equipped)",EquipBase!$S$2,IF(OR(Build!$B$14="(none)",Build!$B$14=""),0,IFERROR(INDEX(GearDB_HASTE_ABILITY,$B$2),0)))+IF(Build!$B$14="(keep equipped)",0,IF($C$2>0,Build!$D$14*INDEX(AugDB_HASTE_ABILITY,$C$2),0)+IF(Build!$E$14="HASTE_ABILITY",Build!$F$14,0)+IF(Build!$G$14="HASTE_ABILITY",Build!$H$14,0)) | V2: =IF(Build!$B$14="(keep equipped)",EquipBase!$T$2,IF(OR(Build!$B$14="(none)",Build!$B$14=""),0,IFERROR(INDEX(GearDB_DUAL_WIELD,$B$2),0)))+IF(Build!$B$14="(keep equipped)",0,IF($C$2>0,Build!$D$14*INDEX(AugDB_DUAL_WIELD,$C$2),0)+IF(Build!$E$14="DUAL_WIELD",Build!$F$14,0)+IF(Build!$G$14="DUAL_WIELD",Build!$H$14,0)) | W2: =IF(Build!$B$14="(keep equipped)",EquipBase!$U$2,IF(OR(Build!$B$14="(none)",Build!$B$14=""),0,IFERROR(INDEX(GearDB_STORETP,$B$2),0)))+IF(Build!$B$14="(keep equipped)",0,IF($C$2>0,Build!$D$14*INDEX(AugDB_STORETP,$C$2),0)+IF(Build!$E$14="STORETP",Build!$F$14,0)+IF(Build!$G$14="STORETP",Build!$H$14,0)) | X2: =IF(Build!$B$14="(keep equipped)",EquipBase!$V$2,IF(OR(Build!$B$14="(none)",Build!$B$14=""),0,IFERROR(INDEX(GearDB_TP_BONUS,$B$2),0)))+IF(Build!$B$14="(keep equipped)",0,IF($C$2>0,Build!$D$14*INDEX(AugDB_TP_BONUS,$C$2),0)+IF(Build!$E$14="TP_BONUS",Build!$F$14,0)+IF(Build!$G$14="TP_BONUS",Build!$H$14,0)) | Y2: =IF(Build!$B$14="(keep equipped)",EquipBase!$W$2,IF(OR(Build!$B$14="(none)",Build!$B$14=""),0,IFERROR(INDEX(GearDB_ALL_WSDMG_ALL_HITS,$B$2),0)))+IF(Build!$B$14="(keep equipped)",0,IF($C$2>0,Build!$D$14*INDEX(AugDB_ALL_WSDMG_ALL_HITS,$C$2),0)+IF(Build!$E$14="ALL_WSDMG_ALL_HITS",Build!$F$14,0)+IF(Build!$G$14="ALL_WSDMG_ALL_HITS",Build!$H$14,0)) | Z2: =IF(Build!$B$14="(keep equipped)",EquipBase!$X$2,IF(OR(Build!$B$14="(none)",Build!$B$14=""),0,IFERROR(INDEX(GearDB_ALL_WSDMG_FIRST_HIT,$B$2),0)))+IF(Build!$B$14="(keep equipped)",0,IF($C$2>0,Build!$D$14*INDEX(AugDB_ALL_WSDMG_FIRST_HIT,$C$2),0)+IF(Build!$E$14="ALL_WSDMG_FIRST_HIT",Build!$F$14,0)+IF(Build!$G$14="ALL_WSDMG_FIRST_HIT",Build!$H$14,0)) | AA2: =IF(Build!$B$14="(keep equipped)",EquipBase!$Y$2,IF(OR(Build!$B$14="(none)",Build!$B$14=""),0,IFERROR(INDEX(GearDB_ANY_FTP_BONUS,$B$2),0)))+IF(Build!$B$14="(keep equipped)",0,IF($C$2>0,Build!$D$14*INDEX(AugDB_ANY_FTP_BONUS,$C$2),0)+IF(Build!$E$14="ANY_FTP_BONUS",Build!$F$14,0)+IF(Build!$G$14="ANY_FTP_BONUS",Build!$H$14,0)) | AB2: =IF(Build!$B$14="(keep equipped)",EquipBase!$Z$2,IF(OR(Build!$B$14="(none)",Build!$B$14=""),0,IFERROR(INDEX(GearDB_WSACC,$B$2),0)))+IF(Build!$B$14="(keep equipped)",0,IF($C$2>0,Build!$D$14*INDEX(AugDB_WSACC,$C$2),0)+IF(Build!$E$14="WSACC",Build!$F$14,0)+IF(Build!$G$14="WSACC",Build!$H$14,0)) | AC2: =IF(Build!$B$14="(keep equipped)",EquipBase!$AA$2,IF(OR(Build!$B$14="(none)",Build!$B$14=""),0,IFERROR(INDEX(GearDB_WSDMG_225,$B$2),0)))+IF(Build!$B$14="(keep equipped)",0,IF($C$2>0,Build!$D$14*INDEX(AugDB_WSDMG_225,$C$2),0)+IF(Build!$E$14="WSDMG_225",Build!$F$14,0)+IF(Build!$G$14="WSDMG_225",Build!$H$14,0))
A3: ammo | B3: =IFERROR(MATCH(Build!$B$15,GearDB_names,0),0) | C3: =IFERROR(MATCH(Build!$C$15,AugDB_labels,0),0) | D3: =IF(Build!$B$15="(keep equipped)",EquipBase!$B$3,IF(OR(Build!$B$15="(none)",Build!$B$15=""),0,IFERROR(INDEX(GearDB_STR,$B$3),0)))+IF(Build!$B$15="(keep equipped)",0,IF($C$3>0,Build!$D$15*INDEX(AugDB_STR,$C$3),0)+IF(Build!$E$15="STR",Build!$F$15,0)+IF(Build!$G$15="STR",Build!$H$15,0)) | E3: =IF(Build!$B$15="(keep equipped)",EquipBase!$C$3,IF(OR(Build!$B$15="(none)",Build!$B$15=""),0,IFERROR(INDEX(GearDB_DEX,$B$3),0)))+IF(Build!$B$15="(keep equipped)",0,IF($C$3>0,Build!$D$15*INDEX(AugDB_DEX,$C$3),0)+IF(Build!$E$15="DEX",Build!$F$15,0)+IF(Build!$G$15="DEX",Build!$H$15,0)) | F3: =IF(Build!$B$15="(keep equipped)",EquipBase!$D$3,IF(OR(Build!$B$15="(none)",Build!$B$15=""),0,IFERROR(INDEX(GearDB_VIT,$B$3),0)))+IF(Build!$B$15="(keep equipped)",0,IF($C$3>0,Build!$D$15*INDEX(AugDB_VIT,$C$3),0)+IF(Build!$E$15="VIT",Build!$F$15,0)+IF(Build!$G$15="VIT",Build!$H$15,0)) | G3: =IF(Build!$B$15="(keep equipped)",EquipBase!$E$3,IF(OR(Build!$B$15="(none)",Build!$B$15=""),0,IFERROR(INDEX(GearDB_AGI,$B$3),0)))+IF(Build!$B$15="(keep equipped)",0,IF($C$3>0,Build!$D$15*INDEX(AugDB_AGI,$C$3),0)+IF(Build!$E$15="AGI",Build!$F$15,0)+IF(Build!$G$15="AGI",Build!$H$15,0)) | H3: =IF(Build!$B$15="(keep equipped)",EquipBase!$F$3,IF(OR(Build!$B$15="(none)",Build!$B$15=""),0,IFERROR(INDEX(GearDB_INT,$B$3),0)))+IF(Build!$B$15="(keep equipped)",0,IF($C$3>0,Build!$D$15*INDEX(AugDB_INT,$C$3),0)+IF(Build!$E$15="INT",Build!$F$15,0)+IF(Build!$G$15="INT",Build!$H$15,0)) | I3: =IF(Build!$B$15="(keep equipped)",EquipBase!$G$3,IF(OR(Build!$B$15="(none)",Build!$B$15=""),0,IFERROR(INDEX(GearDB_MND,$B$3),0)))+IF(Build!$B$15="(keep equipped)",0,IF($C$3>0,Build!$D$15*INDEX(AugDB_MND,$C$3),0)+IF(Build!$E$15="MND",Build!$F$15,0)+IF(Build!$G$15="MND",Build!$H$15,0)) | J3: =IF(Build!$B$15="(keep equipped)",EquipBase!$H$3,IF(OR(Build!$B$15="(none)",Build!$B$15=""),0,IFERROR(INDEX(GearDB_CHR,$B$3),0)))+IF(Build!$B$15="(keep equipped)",0,IF($C$3>0,Build!$D$15*INDEX(AugDB_CHR,$C$3),0)+IF(Build!$E$15="CHR",Build!$F$15,0)+IF(Build!$G$15="CHR",Build!$H$15,0)) | K3: =IF(Build!$B$15="(keep equipped)",EquipBase!$I$3,IF(OR(Build!$B$15="(none)",Build!$B$15=""),0,IFERROR(INDEX(GearDB_ATT,$B$3),0)))+IF(Build!$B$15="(keep equipped)",0,IF($C$3>0,Build!$D$15*INDEX(AugDB_ATT,$C$3),0)+IF(Build!$E$15="ATT",Build!$F$15,0)+IF(Build!$G$15="ATT",Build!$H$15,0)) | L3: =IF(Build!$B$15="(keep equipped)",EquipBase!$J$3,IF(OR(Build!$B$15="(none)",Build!$B$15=""),0,IFERROR(INDEX(GearDB_ATTP,$B$3),0)))+IF(Build!$B$15="(keep equipped)",0,IF($C$3>0,Build!$D$15*INDEX(AugDB_ATTP,$C$3),0)+IF(Build!$E$15="ATTP",Build!$F$15,0)+IF(Build!$G$15="ATTP",Build!$H$15,0)) | M3: =IF(Build!$B$15="(keep equipped)",EquipBase!$K$3,IF(OR(Build!$B$15="(none)",Build!$B$15=""),0,IFERROR(INDEX(GearDB_ACC,$B$3),0)))+IF(Build!$B$15="(keep equipped)",0,IF($C$3>0,Build!$D$15*INDEX(AugDB_ACC,$C$3),0)+IF(Build!$E$15="ACC",Build!$F$15,0)+IF(Build!$G$15="ACC",Build!$H$15,0)) | N3: =IF(Build!$B$15="(keep equipped)",EquipBase!$L$3,IF(OR(Build!$B$15="(none)",Build!$B$15=""),0,IFERROR(INDEX(GearDB_CRITHITRATE,$B$3),0)))+IF(Build!$B$15="(keep equipped)",0,IF($C$3>0,Build!$D$15*INDEX(AugDB_CRITHITRATE,$C$3),0)+IF(Build!$E$15="CRITHITRATE",Build!$F$15,0)+IF(Build!$G$15="CRITHITRATE",Build!$H$15,0)) | O3: =IF(Build!$B$15="(keep equipped)",EquipBase!$M$3,IF(OR(Build!$B$15="(none)",Build!$B$15=""),0,IFERROR(INDEX(GearDB_CRIT_DMG_INCREASE,$B$3),0)))+IF(Build!$B$15="(keep equipped)",0,IF($C$3>0,Build!$D$15*INDEX(AugDB_CRIT_DMG_INCREASE,$C$3),0)+IF(Build!$E$15="CRIT_DMG_INCREASE",Build!$F$15,0)+IF(Build!$G$15="CRIT_DMG_INCREASE",Build!$H$15,0)) | P3: =IF(Build!$B$15="(keep equipped)",EquipBase!$N$3,IF(OR(Build!$B$15="(none)",Build!$B$15=""),0,IFERROR(INDEX(GearDB_DOUBLE_ATTACK,$B$3),0)))+IF(Build!$B$15="(keep equipped)",0,IF($C$3>0,Build!$D$15*INDEX(AugDB_DOUBLE_ATTACK,$C$3),0)+IF(Build!$E$15="DOUBLE_ATTACK",Build!$F$15,0)+IF(Build!$G$15="DOUBLE_ATTACK",Build!$H$15,0)) | Q3: =IF(Build!$B$15="(keep equipped)",EquipBase!$O$3,IF(OR(Build!$B$15="(none)",Build!$B$15=""),0,IFERROR(INDEX(GearDB_TRIPLE_ATTACK,$B$3),0)))+IF(Build!$B$15="(keep equipped)",0,IF($C$3>0,Build!$D$15*INDEX(AugDB_TRIPLE_ATTACK,$C$3),0)+IF(Build!$E$15="TRIPLE_ATTACK",Build!$F$15,0)+IF(Build!$G$15="TRIPLE_ATTACK",Build!$H$15,0)) | R3: =IF(Build!$B$15="(keep equipped)",EquipBase!$P$3,IF(OR(Build!$B$15="(none)",Build!$B$15=""),0,IFERROR(INDEX(GearDB_QUAD_ATTACK,$B$3),0)))+IF(Build!$B$15="(keep equipped)",0,IF($C$3>0,Build!$D$15*INDEX(AugDB_QUAD_ATTACK,$C$3),0)+IF(Build!$E$15="QUAD_ATTACK",Build!$F$15,0)+IF(Build!$G$15="QUAD_ATTACK",Build!$H$15,0)) | S3: =IF(Build!$B$15="(keep equipped)",EquipBase!$Q$3,IF(OR(Build!$B$15="(none)",Build!$B$15=""),0,IFERROR(INDEX(GearDB_HASTE_GEAR,$B$3),0)))+IF(Build!$B$15="(keep equipped)",0,IF($C$3>0,Build!$D$15*INDEX(AugDB_HASTE_GEAR,$C$3),0)+IF(Build!$E$15="HASTE_GEAR",Build!$F$15,0)+IF(Build!$G$15="HASTE_GEAR",Build!$H$15,0)) | T3: =IF(Build!$B$15="(keep equipped)",EquipBase!$R$3,IF(OR(Build!$B$15="(none)",Build!$B$15=""),0,IFERROR(INDEX(GearDB_HASTE_MAGIC,$B$3),0)))+IF(Build!$B$15="(keep equipped)",0,IF($C$3>0,Build!$D$15*INDEX(AugDB_HASTE_MAGIC,$C$3),0)+IF(Build!$E$15="HASTE_MAGIC",Build!$F$15,0)+IF(Build!$G$15="HASTE_MAGIC",Build!$H$15,0)) | U3: =IF(Build!$B$15="(keep equipped)",EquipBase!$S$3,IF(OR(Build!$B$15="(none)",Build!$B$15=""),0,IFERROR(INDEX(GearDB_HASTE_ABILITY,$B$3),0)))+IF(Build!$B$15="(keep equipped)",0,IF($C$3>0,Build!$D$15*INDEX(AugDB_HASTE_ABILITY,$C$3),0)+IF(Build!$E$15="HASTE_ABILITY",Build!$F$15,0)+IF(Build!$G$15="HASTE_ABILITY",Build!$H$15,0)) | V3: =IF(Build!$B$15="(keep equipped)",EquipBase!$T$3,IF(OR(Build!$B$15="(none)",Build!$B$15=""),0,IFERROR(INDEX(GearDB_DUAL_WIELD,$B$3),0)))+IF(Build!$B$15="(keep equipped)",0,IF($C$3>0,Build!$D$15*INDEX(AugDB_DUAL_WIELD,$C$3),0)+IF(Build!$E$15="DUAL_WIELD",Build!$F$15,0)+IF(Build!$G$15="DUAL_WIELD",Build!$H$15,0)) | W3: =IF(Build!$B$15="(keep equipped)",EquipBase!$U$3,IF(OR(Build!$B$15="(none)",Build!$B$15=""),0,IFERROR(INDEX(GearDB_STORETP,$B$3),0)))+IF(Build!$B$15="(keep equipped)",0,IF($C$3>0,Build!$D$15*INDEX(AugDB_STORETP,$C$3),0)+IF(Build!$E$15="STORETP",Build!$F$15,0)+IF(Build!$G$15="STORETP",Build!$H$15,0)) | X3: =IF(Build!$B$15="(keep equipped)",EquipBase!$V$3,IF(OR(Build!$B$15="(none)",Build!$B$15=""),0,IFERROR(INDEX(GearDB_TP_BONUS,$B$3),0)))+IF(Build!$B$15="(keep equipped)",0,IF($C$3>0,Build!$D$15*INDEX(AugDB_TP_BONUS,$C$3),0)+IF(Build!$E$15="TP_BONUS",Build!$F$15,0)+IF(Build!$G$15="TP_BONUS",Build!$H$15,0)) | Y3: =IF(Build!$B$15="(keep equipped)",EquipBase!$W$3,IF(OR(Build!$B$15="(none)",Build!$B$15=""),0,IFERROR(INDEX(GearDB_ALL_WSDMG_ALL_HITS,$B$3),0)))+IF(Build!$B$15="(keep equipped)",0,IF($C$3>0,Build!$D$15*INDEX(AugDB_ALL_WSDMG_ALL_HITS,$C$3),0)+IF(Build!$E$15="ALL_WSDMG_ALL_HITS",Build!$F$15,0)+IF(Build!$G$15="ALL_WSDMG_ALL_HITS",Build!$H$15,0)) | Z3: =IF(Build!$B$15="(keep equipped)",EquipBase!$X$3,IF(OR(Build!$B$15="(none)",Build!$B$15=""),0,IFERROR(INDEX(GearDB_ALL_WSDMG_FIRST_HIT,$B$3),0)))+IF(Build!$B$15="(keep equipped)",0,IF($C$3>0,Build!$D$15*INDEX(AugDB_ALL_WSDMG_FIRST_HIT,$C$3),0)+IF(Build!$E$15="ALL_WSDMG_FIRST_HIT",Build!$F$15,0)+IF(Build!$G$15="ALL_WSDMG_FIRST_HIT",Build!$H$15,0)) | AA3: =IF(Build!$B$15="(keep equipped)",EquipBase!$Y$3,IF(OR(Build!$B$15="(none)",Build!$B$15=""),0,IFERROR(INDEX(GearDB_ANY_FTP_BONUS,$B$3),0)))+IF(Build!$B$15="(keep equipped)",0,IF($C$3>0,Build!$D$15*INDEX(AugDB_ANY_FTP_BONUS,$C$3),0)+IF(Build!$E$15="ANY_FTP_BONUS",Build!$F$15,0)+IF(Build!$G$15="ANY_FTP_BONUS",Build!$H$15,0)) | AB3: =IF(Build!$B$15="(keep equipped)",EquipBase!$Z$3,IF(OR(Build!$B$15="(none)",Build!$B$15=""),0,IFERROR(INDEX(GearDB_WSACC,$B$3),0)))+IF(Build!$B$15="(keep equipped)",0,IF($C$3>0,Build!$D$15*INDEX(AugDB_WSACC,$C$3),0)+IF(Build!$E$15="WSACC",Build!$F$15,0)+IF(Build!$G$15="WSACC",Build!$H$15,0)) | AC3: =IF(Build!$B$15="(keep equipped)",EquipBase!$AA$3,IF(OR(Build!$B$15="(none)",Build!$B$15=""),0,IFERROR(INDEX(GearDB_WSDMG_225,$B$3),0)))+IF(Build!$B$15="(keep equipped)",0,IF($C$3>0,Build!$D$15*INDEX(AugDB_WSDMG_225,$C$3),0)+IF(Build!$E$15="WSDMG_225",Build!$F$15,0)+IF(Build!$G$15="WSDMG_225",Build!$H$15,0))
A4: head | B4: =IFERROR(MATCH(Build!$B$16,GearDB_names,0),0) | C4: =IFERROR(MATCH(Build!$C$16,AugDB_labels,0),0) | D4: =IF(Build!$B$16="(keep equipped)",EquipBase!$B$4,IF(OR(Build!$B$16="(none)",Build!$B$16=""),0,IFERROR(INDEX(GearDB_STR,$B$4),0)))+IF(Build!$B$16="(keep equipped)",0,IF($C$4>0,Build!$D$16*INDEX(AugDB_STR,$C$4),0)+IF(Build!$E$16="STR",Build!$F$16,0)+IF(Build!$G$16="STR",Build!$H$16,0)) | E4: =IF(Build!$B$16="(keep equipped)",EquipBase!$C$4,IF(OR(Build!$B$16="(none)",Build!$B$16=""),0,IFERROR(INDEX(GearDB_DEX,$B$4),0)))+IF(Build!$B$16="(keep equipped)",0,IF($C$4>0,Build!$D$16*INDEX(AugDB_DEX,$C$4),0)+IF(Build!$E$16="DEX",Build!$F$16,0)+IF(Build!$G$16="DEX",Build!$H$16,0)) | F4: =IF(Build!$B$16="(keep equipped)",EquipBase!$D$4,IF(OR(Build!$B$16="(none)",Build!$B$16=""),0,IFERROR(INDEX(GearDB_VIT,$B$4),0)))+IF(Build!$B$16="(keep equipped)",0,IF($C$4>0,Build!$D$16*INDEX(AugDB_VIT,$C$4),0)+IF(Build!$E$16="VIT",Build!$F$16,0)+IF(Build!$G$16="VIT",Build!$H$16,0)) | G4: =IF(Build!$B$16="(keep equipped)",EquipBase!$E$4,IF(OR(Build!$B$16="(none)",Build!$B$16=""),0,IFERROR(INDEX(GearDB_AGI,$B$4),0)))+IF(Build!$B$16="(keep equipped)",0,IF($C$4>0,Build!$D$16*INDEX(AugDB_AGI,$C$4),0)+IF(Build!$E$16="AGI",Build!$F$16,0)+IF(Build!$G$16="AGI",Build!$H$16,0)) | H4: =IF(Build!$B$16="(keep equipped)",EquipBase!$F$4,IF(OR(Build!$B$16="(none)",Build!$B$16=""),0,IFERROR(INDEX(GearDB_INT,$B$4),0)))+IF(Build!$B$16="(keep equipped)",0,IF($C$4>0,Build!$D$16*INDEX(AugDB_INT,$C$4),0)+IF(Build!$E$16="INT",Build!$F$16,0)+IF(Build!$G$16="INT",Build!$H$16,0)) | I4: =IF(Build!$B$16="(keep equipped)",EquipBase!$G$4,IF(OR(Build!$B$16="(none)",Build!$B$16=""),0,IFERROR(INDEX(GearDB_MND,$B$4),0)))+IF(Build!$B$16="(keep equipped)",0,IF($C$4>0,Build!$D$16*INDEX(AugDB_MND,$C$4),0)+IF(Build!$E$16="MND",Build!$F$16,0)+IF(Build!$G$16="MND",Build!$H$16,0)) | J4: =IF(Build!$B$16="(keep equipped)",EquipBase!$H$4,IF(OR(Build!$B$16="(none)",Build!$B$16=""),0,IFERROR(INDEX(GearDB_CHR,$B$4),0)))+IF(Build!$B$16="(keep equipped)",0,IF($C$4>0,Build!$D$16*INDEX(AugDB_CHR,$C$4),0)+IF(Build!$E$16="CHR",Build!$F$16,0)+IF(Build!$G$16="CHR",Build!$H$16,0)) | K4: =IF(Build!$B$16="(keep equipped)",EquipBase!$I$4,IF(OR(Build!$B$16="(none)",Build!$B$16=""),0,IFERROR(INDEX(GearDB_ATT,$B$4),0)))+IF(Build!$B$16="(keep equipped)",0,IF($C$4>0,Build!$D$16*INDEX(AugDB_ATT,$C$4),0)+IF(Build!$E$16="ATT",Build!$F$16,0)+IF(Build!$G$16="ATT",Build!$H$16,0)) | L4: =IF(Build!$B$16="(keep equipped)",EquipBase!$J$4,IF(OR(Build!$B$16="(none)",Build!$B$16=""),0,IFERROR(INDEX(GearDB_ATTP,$B$4),0)))+IF(Build!$B$16="(keep equipped)",0,IF($C$4>0,Build!$D$16*INDEX(AugDB_ATTP,$C$4),0)+IF(Build!$E$16="ATTP",Build!$F$16,0)+IF(Build!$G$16="ATTP",Build!$H$16,0)) | M4: =IF(Build!$B$16="(keep equipped)",EquipBase!$K$4,IF(OR(Build!$B$16="(none)",Build!$B$16=""),0,IFERROR(INDEX(GearDB_ACC,$B$4),0)))+IF(Build!$B$16="(keep equipped)",0,IF($C$4>0,Build!$D$16*INDEX(AugDB_ACC,$C$4),0)+IF(Build!$E$16="ACC",Build!$F$16,0)+IF(Build!$G$16="ACC",Build!$H$16,0)) | N4: =IF(Build!$B$16="(keep equipped)",EquipBase!$L$4,IF(OR(Build!$B$16="(none)",Build!$B$16=""),0,IFERROR(INDEX(GearDB_CRITHITRATE,$B$4),0)))+IF(Build!$B$16="(keep equipped)",0,IF($C$4>0,Build!$D$16*INDEX(AugDB_CRITHITRATE,$C$4),0)+IF(Build!$E$16="CRITHITRATE",Build!$F$16,0)+IF(Build!$G$16="CRITHITRATE",Build!$H$16,0)) | O4: =IF(Build!$B$16="(keep equipped)",EquipBase!$M$4,IF(OR(Build!$B$16="(none)",Build!$B$16=""),0,IFERROR(INDEX(GearDB_CRIT_DMG_INCREASE,$B$4),0)))+IF(Build!$B$16="(keep equipped)",0,IF($C$4>0,Build!$D$16*INDEX(AugDB_CRIT_DMG_INCREASE,$C$4),0)+IF(Build!$E$16="CRIT_DMG_INCREASE",Build!$F$16,0)+IF(Build!$G$16="CRIT_DMG_INCREASE",Build!$H$16,0)) | P4: =IF(Build!$B$16="(keep equipped)",EquipBase!$N$4,IF(OR(Build!$B$16="(none)",Build!$B$16=""),0,IFERROR(INDEX(GearDB_DOUBLE_ATTACK,$B$4),0)))+IF(Build!$B$16="(keep equipped)",0,IF($C$4>0,Build!$D$16*INDEX(AugDB_DOUBLE_ATTACK,$C$4),0)+IF(Build!$E$16="DOUBLE_ATTACK",Build!$F$16,0)+IF(Build!$G$16="DOUBLE_ATTACK",Build!$H$16,0)) | Q4: =IF(Build!$B$16="(keep equipped)",EquipBase!$O$4,IF(OR(Build!$B$16="(none)",Build!$B$16=""),0,IFERROR(INDEX(GearDB_TRIPLE_ATTACK,$B$4),0)))+IF(Build!$B$16="(keep equipped)",0,IF($C$4>0,Build!$D$16*INDEX(AugDB_TRIPLE_ATTACK,$C$4),0)+IF(Build!$E$16="TRIPLE_ATTACK",Build!$F$16,0)+IF(Build!$G$16="TRIPLE_ATTACK",Build!$H$16,0)) | R4: =IF(Build!$B$16="(keep equipped)",EquipBase!$P$4,IF(OR(Build!$B$16="(none)",Build!$B$16=""),0,IFERROR(INDEX(GearDB_QUAD_ATTACK,$B$4),0)))+IF(Build!$B$16="(keep equipped)",0,IF($C$4>0,Build!$D$16*INDEX(AugDB_QUAD_ATTACK,$C$4),0)+IF(Build!$E$16="QUAD_ATTACK",Build!$F$16,0)+IF(Build!$G$16="QUAD_ATTACK",Build!$H$16,0)) | S4: =IF(Build!$B$16="(keep equipped)",EquipBase!$Q$4,IF(OR(Build!$B$16="(none)",Build!$B$16=""),0,IFERROR(INDEX(GearDB_HASTE_GEAR,$B$4),0)))+IF(Build!$B$16="(keep equipped)",0,IF($C$4>0,Build!$D$16*INDEX(AugDB_HASTE_GEAR,$C$4),0)+IF(Build!$E$16="HASTE_GEAR",Build!$F$16,0)+IF(Build!$G$16="HASTE_GEAR",Build!$H$16,0)) | T4: =IF(Build!$B$16="(keep equipped)",EquipBase!$R$4,IF(OR(Build!$B$16="(none)",Build!$B$16=""),0,IFERROR(INDEX(GearDB_HASTE_MAGIC,$B$4),0)))+IF(Build!$B$16="(keep equipped)",0,IF($C$4>0,Build!$D$16*INDEX(AugDB_HASTE_MAGIC,$C$4),0)+IF(Build!$E$16="HASTE_MAGIC",Build!$F$16,0)+IF(Build!$G$16="HASTE_MAGIC",Build!$H$16,0)) | U4: =IF(Build!$B$16="(keep equipped)",EquipBase!$S$4,IF(OR(Build!$B$16="(none)",Build!$B$16=""),0,IFERROR(INDEX(GearDB_HASTE_ABILITY,$B$4),0)))+IF(Build!$B$16="(keep equipped)",0,IF($C$4>0,Build!$D$16*INDEX(AugDB_HASTE_ABILITY,$C$4),0)+IF(Build!$E$16="HASTE_ABILITY",Build!$F$16,0)+IF(Build!$G$16="HASTE_ABILITY",Build!$H$16,0)) | V4: =IF(Build!$B$16="(keep equipped)",EquipBase!$T$4,IF(OR(Build!$B$16="(none)",Build!$B$16=""),0,IFERROR(INDEX(GearDB_DUAL_WIELD,$B$4),0)))+IF(Build!$B$16="(keep equipped)",0,IF($C$4>0,Build!$D$16*INDEX(AugDB_DUAL_WIELD,$C$4),0)+IF(Build!$E$16="DUAL_WIELD",Build!$F$16,0)+IF(Build!$G$16="DUAL_WIELD",Build!$H$16,0)) | W4: =IF(Build!$B$16="(keep equipped)",EquipBase!$U$4,IF(OR(Build!$B$16="(none)",Build!$B$16=""),0,IFERROR(INDEX(GearDB_STORETP,$B$4),0)))+IF(Build!$B$16="(keep equipped)",0,IF($C$4>0,Build!$D$16*INDEX(AugDB_STORETP,$C$4),0)+IF(Build!$E$16="STORETP",Build!$F$16,0)+IF(Build!$G$16="STORETP",Build!$H$16,0)) | X4: =IF(Build!$B$16="(keep equipped)",EquipBase!$V$4,IF(OR(Build!$B$16="(none)",Build!$B$16=""),0,IFERROR(INDEX(GearDB_TP_BONUS,$B$4),0)))+IF(Build!$B$16="(keep equipped)",0,IF($C$4>0,Build!$D$16*INDEX(AugDB_TP_BONUS,$C$4),0)+IF(Build!$E$16="TP_BONUS",Build!$F$16,0)+IF(Build!$G$16="TP_BONUS",Build!$H$16,0)) | Y4: =IF(Build!$B$16="(keep equipped)",EquipBase!$W$4,IF(OR(Build!$B$16="(none)",Build!$B$16=""),0,IFERROR(INDEX(GearDB_ALL_WSDMG_ALL_HITS,$B$4),0)))+IF(Build!$B$16="(keep equipped)",0,IF($C$4>0,Build!$D$16*INDEX(AugDB_ALL_WSDMG_ALL_HITS,$C$4),0)+IF(Build!$E$16="ALL_WSDMG_ALL_HITS",Build!$F$16,0)+IF(Build!$G$16="ALL_WSDMG_ALL_HITS",Build!$H$16,0)) | Z4: =IF(Build!$B$16="(keep equipped)",EquipBase!$X$4,IF(OR(Build!$B$16="(none)",Build!$B$16=""),0,IFERROR(INDEX(GearDB_ALL_WSDMG_FIRST_HIT,$B$4),0)))+IF(Build!$B$16="(keep equipped)",0,IF($C$4>0,Build!$D$16*INDEX(AugDB_ALL_WSDMG_FIRST_HIT,$C$4),0)+IF(Build!$E$16="ALL_WSDMG_FIRST_HIT",Build!$F$16,0)+IF(Build!$G$16="ALL_WSDMG_FIRST_HIT",Build!$H$16,0)) | AA4: =IF(Build!$B$16="(keep equipped)",EquipBase!$Y$4,IF(OR(Build!$B$16="(none)",Build!$B$16=""),0,IFERROR(INDEX(GearDB_ANY_FTP_BONUS,$B$4),0)))+IF(Build!$B$16="(keep equipped)",0,IF($C$4>0,Build!$D$16*INDEX(AugDB_ANY_FTP_BONUS,$C$4),0)+IF(Build!$E$16="ANY_FTP_BONUS",Build!$F$16,0)+IF(Build!$G$16="ANY_FTP_BONUS",Build!$H$16,0)) | AB4: =IF(Build!$B$16="(keep equipped)",EquipBase!$Z$4,IF(OR(Build!$B$16="(none)",Build!$B$16=""),0,IFERROR(INDEX(GearDB_WSACC,$B$4),0)))+IF(Build!$B$16="(keep equipped)",0,IF($C$4>0,Build!$D$16*INDEX(AugDB_WSACC,$C$4),0)+IF(Build!$E$16="WSACC",Build!$F$16,0)+IF(Build!$G$16="WSACC",Build!$H$16,0)) | AC4: =IF(Build!$B$16="(keep equipped)",EquipBase!$AA$4,IF(OR(Build!$B$16="(none)",Build!$B$16=""),0,IFERROR(INDEX(GearDB_WSDMG_225,$B$4),0)))+IF(Build!$B$16="(keep equipped)",0,IF($C$4>0,Build!$D$16*INDEX(AugDB_WSDMG_225,$C$4),0)+IF(Build!$E$16="WSDMG_225",Build!$F$16,0)+IF(Build!$G$16="WSDMG_225",Build!$H$16,0))
A5: body | B5: =IFERROR(MATCH(Build!$B$17,GearDB_names,0),0) | C5: =IFERROR(MATCH(Build!$C$17,AugDB_labels,0),0) | D5: =IF(Build!$B$17="(keep equipped)",EquipBase!$B$5,IF(OR(Build!$B$17="(none)",Build!$B$17=""),0,IFERROR(INDEX(GearDB_STR,$B$5),0)))+IF(Build!$B$17="(keep equipped)",0,IF($C$5>0,Build!$D$17*INDEX(AugDB_STR,$C$5),0)+IF(Build!$E$17="STR",Build!$F$17,0)+IF(Build!$G$17="STR",Build!$H$17,0)) | E5: =IF(Build!$B$17="(keep equipped)",EquipBase!$C$5,IF(OR(Build!$B$17="(none)",Build!$B$17=""),0,IFERROR(INDEX(GearDB_DEX,$B$5),0)))+IF(Build!$B$17="(keep equipped)",0,IF($C$5>0,Build!$D$17*INDEX(AugDB_DEX,$C$5),0)+IF(Build!$E$17="DEX",Build!$F$17,0)+IF(Build!$G$17="DEX",Build!$H$17,0)) | F5: =IF(Build!$B$17="(keep equipped)",EquipBase!$D$5,IF(OR(Build!$B$17="(none)",Build!$B$17=""),0,IFERROR(INDEX(GearDB_VIT,$B$5),0)))+IF(Build!$B$17="(keep equipped)",0,IF($C$5>0,Build!$D$17*INDEX(AugDB_VIT,$C$5),0)+IF(Build!$E$17="VIT",Build!$F$17,0)+IF(Build!$G$17="VIT",Build!$H$17,0)) | G5: =IF(Build!$B$17="(keep equipped)",EquipBase!$E$5,IF(OR(Build!$B$17="(none)",Build!$B$17=""),0,IFERROR(INDEX(GearDB_AGI,$B$5),0)))+IF(Build!$B$17="(keep equipped)",0,IF($C$5>0,Build!$D$17*INDEX(AugDB_AGI,$C$5),0)+IF(Build!$E$17="AGI",Build!$F$17,0)+IF(Build!$G$17="AGI",Build!$H$17,0)) | H5: =IF(Build!$B$17="(keep equipped)",EquipBase!$F$5,IF(OR(Build!$B$17="(none)",Build!$B$17=""),0,IFERROR(INDEX(GearDB_INT,$B$5),0)))+IF(Build!$B$17="(keep equipped)",0,IF($C$5>0,Build!$D$17*INDEX(AugDB_INT,$C$5),0)+IF(Build!$E$17="INT",Build!$F$17,0)+IF(Build!$G$17="INT",Build!$H$17,0)) | I5: =IF(Build!$B$17="(keep equipped)",EquipBase!$G$5,IF(OR(Build!$B$17="(none)",Build!$B$17=""),0,IFERROR(INDEX(GearDB_MND,$B$5),0)))+IF(Build!$B$17="(keep equipped)",0,IF($C$5>0,Build!$D$17*INDEX(AugDB_MND,$C$5),0)+IF(Build!$E$17="MND",Build!$F$17,0)+IF(Build!$G$17="MND",Build!$H$17,0)) | J5: =IF(Build!$B$17="(keep equipped)",EquipBase!$H$5,IF(OR(Build!$B$17="(none)",Build!$B$17=""),0,IFERROR(INDEX(GearDB_CHR,$B$5),0)))+IF(Build!$B$17="(keep equipped)",0,IF($C$5>0,Build!$D$17*INDEX(AugDB_CHR,$C$5),0)+IF(Build!$E$17="CHR",Build!$F$17,0)+IF(Build!$G$17="CHR",Build!$H$17,0)) | K5: =IF(Build!$B$17="(keep equipped)",EquipBase!$I$5,IF(OR(Build!$B$17="(none)",Build!$B$17=""),0,IFERROR(INDEX(GearDB_ATT,$B$5),0)))+IF(Build!$B$17="(keep equipped)",0,IF($C$5>0,Build!$D$17*INDEX(AugDB_ATT,$C$5),0)+IF(Build!$E$17="ATT",Build!$F$17,0)+IF(Build!$G$17="ATT",Build!$H$17,0)) | L5: =IF(Build!$B$17="(keep equipped)",EquipBase!$J$5,IF(OR(Build!$B$17="(none)",Build!$B$17=""),0,IFERROR(INDEX(GearDB_ATTP,$B$5),0)))+IF(Build!$B$17="(keep equipped)",0,IF($C$5>0,Build!$D$17*INDEX(AugDB_ATTP,$C$5),0)+IF(Build!$E$17="ATTP",Build!$F$17,0)+IF(Build!$G$17="ATTP",Build!$H$17,0)) | M5: =IF(Build!$B$17="(keep equipped)",EquipBase!$K$5,IF(OR(Build!$B$17="(none)",Build!$B$17=""),0,IFERROR(INDEX(GearDB_ACC,$B$5),0)))+IF(Build!$B$17="(keep equipped)",0,IF($C$5>0,Build!$D$17*INDEX(AugDB_ACC,$C$5),0)+IF(Build!$E$17="ACC",Build!$F$17,0)+IF(Build!$G$17="ACC",Build!$H$17,0)) | N5: =IF(Build!$B$17="(keep equipped)",EquipBase!$L$5,IF(OR(Build!$B$17="(none)",Build!$B$17=""),0,IFERROR(INDEX(GearDB_CRITHITRATE,$B$5),0)))+IF(Build!$B$17="(keep equipped)",0,IF($C$5>0,Build!$D$17*INDEX(AugDB_CRITHITRATE,$C$5),0)+IF(Build!$E$17="CRITHITRATE",Build!$F$17,0)+IF(Build!$G$17="CRITHITRATE",Build!$H$17,0)) | O5: =IF(Build!$B$17="(keep equipped)",EquipBase!$M$5,IF(OR(Build!$B$17="(none)",Build!$B$17=""),0,IFERROR(INDEX(GearDB_CRIT_DMG_INCREASE,$B$5),0)))+IF(Build!$B$17="(keep equipped)",0,IF($C$5>0,Build!$D$17*INDEX(AugDB_CRIT_DMG_INCREASE,$C$5),0)+IF(Build!$E$17="CRIT_DMG_INCREASE",Build!$F$17,0)+IF(Build!$G$17="CRIT_DMG_INCREASE",Build!$H$17,0)) | P5: =IF(Build!$B$17="(keep equipped)",EquipBase!$N$5,IF(OR(Build!$B$17="(none)",Build!$B$17=""),0,IFERROR(INDEX(GearDB_DOUBLE_ATTACK,$B$5),0)))+IF(Build!$B$17="(keep equipped)",0,IF($C$5>0,Build!$D$17*INDEX(AugDB_DOUBLE_ATTACK,$C$5),0)+IF(Build!$E$17="DOUBLE_ATTACK",Build!$F$17,0)+IF(Build!$G$17="DOUBLE_ATTACK",Build!$H$17,0)) | Q5: =IF(Build!$B$17="(keep equipped)",EquipBase!$O$5,IF(OR(Build!$B$17="(none)",Build!$B$17=""),0,IFERROR(INDEX(GearDB_TRIPLE_ATTACK,$B$5),0)))+IF(Build!$B$17="(keep equipped)",0,IF($C$5>0,Build!$D$17*INDEX(AugDB_TRIPLE_ATTACK,$C$5),0)+IF(Build!$E$17="TRIPLE_ATTACK",Build!$F$17,0)+IF(Build!$G$17="TRIPLE_ATTACK",Build!$H$17,0)) | R5: =IF(Build!$B$17="(keep equipped)",EquipBase!$P$5,IF(OR(Build!$B$17="(none)",Build!$B$17=""),0,IFERROR(INDEX(GearDB_QUAD_ATTACK,$B$5),0)))+IF(Build!$B$17="(keep equipped)",0,IF($C$5>0,Build!$D$17*INDEX(AugDB_QUAD_ATTACK,$C$5),0)+IF(Build!$E$17="QUAD_ATTACK",Build!$F$17,0)+IF(Build!$G$17="QUAD_ATTACK",Build!$H$17,0)) | S5: =IF(Build!$B$17="(keep equipped)",EquipBase!$Q$5,IF(OR(Build!$B$17="(none)",Build!$B$17=""),0,IFERROR(INDEX(GearDB_HASTE_GEAR,$B$5),0)))+IF(Build!$B$17="(keep equipped)",0,IF($C$5>0,Build!$D$17*INDEX(AugDB_HASTE_GEAR,$C$5),0)+IF(Build!$E$17="HASTE_GEAR",Build!$F$17,0)+IF(Build!$G$17="HASTE_GEAR",Build!$H$17,0)) | T5: =IF(Build!$B$17="(keep equipped)",EquipBase!$R$5,IF(OR(Build!$B$17="(none)",Build!$B$17=""),0,IFERROR(INDEX(GearDB_HASTE_MAGIC,$B$5),0)))+IF(Build!$B$17="(keep equipped)",0,IF($C$5>0,Build!$D$17*INDEX(AugDB_HASTE_MAGIC,$C$5),0)+IF(Build!$E$17="HASTE_MAGIC",Build!$F$17,0)+IF(Build!$G$17="HASTE_MAGIC",Build!$H$17,0)) | U5: =IF(Build!$B$17="(keep equipped)",EquipBase!$S$5,IF(OR(Build!$B$17="(none)",Build!$B$17=""),0,IFERROR(INDEX(GearDB_HASTE_ABILITY,$B$5),0)))+IF(Build!$B$17="(keep equipped)",0,IF($C$5>0,Build!$D$17*INDEX(AugDB_HASTE_ABILITY,$C$5),0)+IF(Build!$E$17="HASTE_ABILITY",Build!$F$17,0)+IF(Build!$G$17="HASTE_ABILITY",Build!$H$17,0)) | V5: =IF(Build!$B$17="(keep equipped)",EquipBase!$T$5,IF(OR(Build!$B$17="(none)",Build!$B$17=""),0,IFERROR(INDEX(GearDB_DUAL_WIELD,$B$5),0)))+IF(Build!$B$17="(keep equipped)",0,IF($C$5>0,Build!$D$17*INDEX(AugDB_DUAL_WIELD,$C$5),0)+IF(Build!$E$17="DUAL_WIELD",Build!$F$17,0)+IF(Build!$G$17="DUAL_WIELD",Build!$H$17,0)) | W5: =IF(Build!$B$17="(keep equipped)",EquipBase!$U$5,IF(OR(Build!$B$17="(none)",Build!$B$17=""),0,IFERROR(INDEX(GearDB_STORETP,$B$5),0)))+IF(Build!$B$17="(keep equipped)",0,IF($C$5>0,Build!$D$17*INDEX(AugDB_STORETP,$C$5),0)+IF(Build!$E$17="STORETP",Build!$F$17,0)+IF(Build!$G$17="STORETP",Build!$H$17,0)) | X5: =IF(Build!$B$17="(keep equipped)",EquipBase!$V$5,IF(OR(Build!$B$17="(none)",Build!$B$17=""),0,IFERROR(INDEX(GearDB_TP_BONUS,$B$5),0)))+IF(Build!$B$17="(keep equipped)",0,IF($C$5>0,Build!$D$17*INDEX(AugDB_TP_BONUS,$C$5),0)+IF(Build!$E$17="TP_BONUS",Build!$F$17,0)+IF(Build!$G$17="TP_BONUS",Build!$H$17,0)) | Y5: =IF(Build!$B$17="(keep equipped)",EquipBase!$W$5,IF(OR(Build!$B$17="(none)",Build!$B$17=""),0,IFERROR(INDEX(GearDB_ALL_WSDMG_ALL_HITS,$B$5),0)))+IF(Build!$B$17="(keep equipped)",0,IF($C$5>0,Build!$D$17*INDEX(AugDB_ALL_WSDMG_ALL_HITS,$C$5),0)+IF(Build!$E$17="ALL_WSDMG_ALL_HITS",Build!$F$17,0)+IF(Build!$G$17="ALL_WSDMG_ALL_HITS",Build!$H$17,0)) | Z5: =IF(Build!$B$17="(keep equipped)",EquipBase!$X$5,IF(OR(Build!$B$17="(none)",Build!$B$17=""),0,IFERROR(INDEX(GearDB_ALL_WSDMG_FIRST_HIT,$B$5),0)))+IF(Build!$B$17="(keep equipped)",0,IF($C$5>0,Build!$D$17*INDEX(AugDB_ALL_WSDMG_FIRST_HIT,$C$5),0)+IF(Build!$E$17="ALL_WSDMG_FIRST_HIT",Build!$F$17,0)+IF(Build!$G$17="ALL_WSDMG_FIRST_HIT",Build!$H$17,0)) | AA5: =IF(Build!$B$17="(keep equipped)",EquipBase!$Y$5,IF(OR(Build!$B$17="(none)",Build!$B$17=""),0,IFERROR(INDEX(GearDB_ANY_FTP_BONUS,$B$5),0)))+IF(Build!$B$17="(keep equipped)",0,IF($C$5>0,Build!$D$17*INDEX(AugDB_ANY_FTP_BONUS,$C$5),0)+IF(Build!$E$17="ANY_FTP_BONUS",Build!$F$17,0)+IF(Build!$G$17="ANY_FTP_BONUS",Build!$H$17,0)) | AB5: =IF(Build!$B$17="(keep equipped)",EquipBase!$Z$5,IF(OR(Build!$B$17="(none)",Build!$B$17=""),0,IFERROR(INDEX(GearDB_WSACC,$B$5),0)))+IF(Build!$B$17="(keep equipped)",0,IF($C$5>0,Build!$D$17*INDEX(AugDB_WSACC,$C$5),0)+IF(Build!$E$17="WSACC",Build!$F$17,0)+IF(Build!$G$17="WSACC",Build!$H$17,0)) | AC5: =IF(Build!$B$17="(keep equipped)",EquipBase!$AA$5,IF(OR(Build!$B$17="(none)",Build!$B$17=""),0,IFERROR(INDEX(GearDB_WSDMG_225,$B$5),0)))+IF(Build!$B$17="(keep equipped)",0,IF($C$5>0,Build!$D$17*INDEX(AugDB_WSDMG_225,$C$5),0)+IF(Build!$E$17="WSDMG_225",Build!$F$17,0)+IF(Build!$G$17="WSDMG_225",Build!$H$17,0))
A6: hands | B6: =IFERROR(MATCH(Build!$B$18,GearDB_names,0),0) | C6: =IFERROR(MATCH(Build!$C$18,AugDB_labels,0),0) | D6: =IF(Build!$B$18="(keep equipped)",EquipBase!$B$6,IF(OR(Build!$B$18="(none)",Build!$B$18=""),0,IFERROR(INDEX(GearDB_STR,$B$6),0)))+IF(Build!$B$18="(keep equipped)",0,IF($C$6>0,Build!$D$18*INDEX(AugDB_STR,$C$6),0)+IF(Build!$E$18="STR",Build!$F$18,0)+IF(Build!$G$18="STR",Build!$H$18,0)) | E6: =IF(Build!$B$18="(keep equipped)",EquipBase!$C$6,IF(OR(Build!$B$18="(none)",Build!$B$18=""),0,IFERROR(INDEX(GearDB_DEX,$B$6),0)))+IF(Build!$B$18="(keep equipped)",0,IF($C$6>0,Build!$D$18*INDEX(AugDB_DEX,$C$6),0)+IF(Build!$E$18="DEX",Build!$F$18,0)+IF(Build!$G$18="DEX",Build!$H$18,0)) | F6: =IF(Build!$B$18="(keep equipped)",EquipBase!$D$6,IF(OR(Build!$B$18="(none)",Build!$B$18=""),0,IFERROR(INDEX(GearDB_VIT,$B$6),0)))+IF(Build!$B$18="(keep equipped)",0,IF($C$6>0,Build!$D$18*INDEX(AugDB_VIT,$C$6),0)+IF(Build!$E$18="VIT",Build!$F$18,0)+IF(Build!$G$18="VIT",Build!$H$18,0)) | G6: =IF(Build!$B$18="(keep equipped)",EquipBase!$E$6,IF(OR(Build!$B$18="(none)",Build!$B$18=""),0,IFERROR(INDEX(GearDB_AGI,$B$6),0)))+IF(Build!$B$18="(keep equipped)",0,IF($C$6>0,Build!$D$18*INDEX(AugDB_AGI,$C$6),0)+IF(Build!$E$18="AGI",Build!$F$18,0)+IF(Build!$G$18="AGI",Build!$H$18,0)) | H6: =IF(Build!$B$18="(keep equipped)",EquipBase!$F$6,IF(OR(Build!$B$18="(none)",Build!$B$18=""),0,IFERROR(INDEX(GearDB_INT,$B$6),0)))+IF(Build!$B$18="(keep equipped)",0,IF($C$6>0,Build!$D$18*INDEX(AugDB_INT,$C$6),0)+IF(Build!$E$18="INT",Build!$F$18,0)+IF(Build!$G$18="INT",Build!$H$18,0)) | I6: =IF(Build!$B$18="(keep equipped)",EquipBase!$G$6,IF(OR(Build!$B$18="(none)",Build!$B$18=""),0,IFERROR(INDEX(GearDB_MND,$B$6),0)))+IF(Build!$B$18="(keep equipped)",0,IF($C$6>0,Build!$D$18*INDEX(AugDB_MND,$C$6),0)+IF(Build!$E$18="MND",Build!$F$18,0)+IF(Build!$G$18="MND",Build!$H$18,0)) | J6: =IF(Build!$B$18="(keep equipped)",EquipBase!$H$6,IF(OR(Build!$B$18="(none)",Build!$B$18=""),0,IFERROR(INDEX(GearDB_CHR,$B$6),0)))+IF(Build!$B$18="(keep equipped)",0,IF($C$6>0,Build!$D$18*INDEX(AugDB_CHR,$C$6),0)+IF(Build!$E$18="CHR",Build!$F$18,0)+IF(Build!$G$18="CHR",Build!$H$18,0)) | K6: =IF(Build!$B$18="(keep equipped)",EquipBase!$I$6,IF(OR(Build!$B$18="(none)",Build!$B$18=""),0,IFERROR(INDEX(GearDB_ATT,$B$6),0)))+IF(Build!$B$18="(keep equipped)",0,IF($C$6>0,Build!$D$18*INDEX(AugDB_ATT,$C$6),0)+IF(Build!$E$18="ATT",Build!$F$18,0)+IF(Build!$G$18="ATT",Build!$H$18,0)) | L6: =IF(Build!$B$18="(keep equipped)",EquipBase!$J$6,IF(OR(Build!$B$18="(none)",Build!$B$18=""),0,IFERROR(INDEX(GearDB_ATTP,$B$6),0)))+IF(Build!$B$18="(keep equipped)",0,IF($C$6>0,Build!$D$18*INDEX(AugDB_ATTP,$C$6),0)+IF(Build!$E$18="ATTP",Build!$F$18,0)+IF(Build!$G$18="ATTP",Build!$H$18,0)) | M6: =IF(Build!$B$18="(keep equipped)",EquipBase!$K$6,IF(OR(Build!$B$18="(none)",Build!$B$18=""),0,IFERROR(INDEX(GearDB_ACC,$B$6),0)))+IF(Build!$B$18="(keep equipped)",0,IF($C$6>0,Build!$D$18*INDEX(AugDB_ACC,$C$6),0)+IF(Build!$E$18="ACC",Build!$F$18,0)+IF(Build!$G$18="ACC",Build!$H$18,0)) | N6: =IF(Build!$B$18="(keep equipped)",EquipBase!$L$6,IF(OR(Build!$B$18="(none)",Build!$B$18=""),0,IFERROR(INDEX(GearDB_CRITHITRATE,$B$6),0)))+IF(Build!$B$18="(keep equipped)",0,IF($C$6>0,Build!$D$18*INDEX(AugDB_CRITHITRATE,$C$6),0)+IF(Build!$E$18="CRITHITRATE",Build!$F$18,0)+IF(Build!$G$18="CRITHITRATE",Build!$H$18,0)) | O6: =IF(Build!$B$18="(keep equipped)",EquipBase!$M$6,IF(OR(Build!$B$18="(none)",Build!$B$18=""),0,IFERROR(INDEX(GearDB_CRIT_DMG_INCREASE,$B$6),0)))+IF(Build!$B$18="(keep equipped)",0,IF($C$6>0,Build!$D$18*INDEX(AugDB_CRIT_DMG_INCREASE,$C$6),0)+IF(Build!$E$18="CRIT_DMG_INCREASE",Build!$F$18,0)+IF(Build!$G$18="CRIT_DMG_INCREASE",Build!$H$18,0)) | P6: =IF(Build!$B$18="(keep equipped)",EquipBase!$N$6,IF(OR(Build!$B$18="(none)",Build!$B$18=""),0,IFERROR(INDEX(GearDB_DOUBLE_ATTACK,$B$6),0)))+IF(Build!$B$18="(keep equipped)",0,IF($C$6>0,Build!$D$18*INDEX(AugDB_DOUBLE_ATTACK,$C$6),0)+IF(Build!$E$18="DOUBLE_ATTACK",Build!$F$18,0)+IF(Build!$G$18="DOUBLE_ATTACK",Build!$H$18,0)) | Q6: =IF(Build!$B$18="(keep equipped)",EquipBase!$O$6,IF(OR(Build!$B$18="(none)",Build!$B$18=""),0,IFERROR(INDEX(GearDB_TRIPLE_ATTACK,$B$6),0)))+IF(Build!$B$18="(keep equipped)",0,IF($C$6>0,Build!$D$18*INDEX(AugDB_TRIPLE_ATTACK,$C$6),0)+IF(Build!$E$18="TRIPLE_ATTACK",Build!$F$18,0)+IF(Build!$G$18="TRIPLE_ATTACK",Build!$H$18,0)) | R6: =IF(Build!$B$18="(keep equipped)",EquipBase!$P$6,IF(OR(Build!$B$18="(none)",Build!$B$18=""),0,IFERROR(INDEX(GearDB_QUAD_ATTACK,$B$6),0)))+IF(Build!$B$18="(keep equipped)",0,IF($C$6>0,Build!$D$18*INDEX(AugDB_QUAD_ATTACK,$C$6),0)+IF(Build!$E$18="QUAD_ATTACK",Build!$F$18,0)+IF(Build!$G$18="QUAD_ATTACK",Build!$H$18,0)) | S6: =IF(Build!$B$18="(keep equipped)",EquipBase!$Q$6,IF(OR(Build!$B$18="(none)",Build!$B$18=""),0,IFERROR(INDEX(GearDB_HASTE_GEAR,$B$6),0)))+IF(Build!$B$18="(keep equipped)",0,IF($C$6>0,Build!$D$18*INDEX(AugDB_HASTE_GEAR,$C$6),0)+IF(Build!$E$18="HASTE_GEAR",Build!$F$18,0)+IF(Build!$G$18="HASTE_GEAR",Build!$H$18,0)) | T6: =IF(Build!$B$18="(keep equipped)",EquipBase!$R$6,IF(OR(Build!$B$18="(none)",Build!$B$18=""),0,IFERROR(INDEX(GearDB_HASTE_MAGIC,$B$6),0)))+IF(Build!$B$18="(keep equipped)",0,IF($C$6>0,Build!$D$18*INDEX(AugDB_HASTE_MAGIC,$C$6),0)+IF(Build!$E$18="HASTE_MAGIC",Build!$F$18,0)+IF(Build!$G$18="HASTE_MAGIC",Build!$H$18,0)) | U6: =IF(Build!$B$18="(keep equipped)",EquipBase!$S$6,IF(OR(Build!$B$18="(none)",Build!$B$18=""),0,IFERROR(INDEX(GearDB_HASTE_ABILITY,$B$6),0)))+IF(Build!$B$18="(keep equipped)",0,IF($C$6>0,Build!$D$18*INDEX(AugDB_HASTE_ABILITY,$C$6),0)+IF(Build!$E$18="HASTE_ABILITY",Build!$F$18,0)+IF(Build!$G$18="HASTE_ABILITY",Build!$H$18,0)) | V6: =IF(Build!$B$18="(keep equipped)",EquipBase!$T$6,IF(OR(Build!$B$18="(none)",Build!$B$18=""),0,IFERROR(INDEX(GearDB_DUAL_WIELD,$B$6),0)))+IF(Build!$B$18="(keep equipped)",0,IF($C$6>0,Build!$D$18*INDEX(AugDB_DUAL_WIELD,$C$6),0)+IF(Build!$E$18="DUAL_WIELD",Build!$F$18,0)+IF(Build!$G$18="DUAL_WIELD",Build!$H$18,0)) | W6: =IF(Build!$B$18="(keep equipped)",EquipBase!$U$6,IF(OR(Build!$B$18="(none)",Build!$B$18=""),0,IFERROR(INDEX(GearDB_STORETP,$B$6),0)))+IF(Build!$B$18="(keep equipped)",0,IF($C$6>0,Build!$D$18*INDEX(AugDB_STORETP,$C$6),0)+IF(Build!$E$18="STORETP",Build!$F$18,0)+IF(Build!$G$18="STORETP",Build!$H$18,0)) | X6: =IF(Build!$B$18="(keep equipped)",EquipBase!$V$6,IF(OR(Build!$B$18="(none)",Build!$B$18=""),0,IFERROR(INDEX(GearDB_TP_BONUS,$B$6),0)))+IF(Build!$B$18="(keep equipped)",0,IF($C$6>0,Build!$D$18*INDEX(AugDB_TP_BONUS,$C$6),0)+IF(Build!$E$18="TP_BONUS",Build!$F$18,0)+IF(Build!$G$18="TP_BONUS",Build!$H$18,0)) | Y6: =IF(Build!$B$18="(keep equipped)",EquipBase!$W$6,IF(OR(Build!$B$18="(none)",Build!$B$18=""),0,IFERROR(INDEX(GearDB_ALL_WSDMG_ALL_HITS,$B$6),0)))+IF(Build!$B$18="(keep equipped)",0,IF($C$6>0,Build!$D$18*INDEX(AugDB_ALL_WSDMG_ALL_HITS,$C$6),0)+IF(Build!$E$18="ALL_WSDMG_ALL_HITS",Build!$F$18,0)+IF(Build!$G$18="ALL_WSDMG_ALL_HITS",Build!$H$18,0)) | Z6: =IF(Build!$B$18="(keep equipped)",EquipBase!$X$6,IF(OR(Build!$B$18="(none)",Build!$B$18=""),0,IFERROR(INDEX(GearDB_ALL_WSDMG_FIRST_HIT,$B$6),0)))+IF(Build!$B$18="(keep equipped)",0,IF($C$6>0,Build!$D$18*INDEX(AugDB_ALL_WSDMG_FIRST_HIT,$C$6),0)+IF(Build!$E$18="ALL_WSDMG_FIRST_HIT",Build!$F$18,0)+IF(Build!$G$18="ALL_WSDMG_FIRST_HIT",Build!$H$18,0)) | AA6: =IF(Build!$B$18="(keep equipped)",EquipBase!$Y$6,IF(OR(Build!$B$18="(none)",Build!$B$18=""),0,IFERROR(INDEX(GearDB_ANY_FTP_BONUS,$B$6),0)))+IF(Build!$B$18="(keep equipped)",0,IF($C$6>0,Build!$D$18*INDEX(AugDB_ANY_FTP_BONUS,$C$6),0)+IF(Build!$E$18="ANY_FTP_BONUS",Build!$F$18,0)+IF(Build!$G$18="ANY_FTP_BONUS",Build!$H$18,0)) | AB6: =IF(Build!$B$18="(keep equipped)",EquipBase!$Z$6,IF(OR(Build!$B$18="(none)",Build!$B$18=""),0,IFERROR(INDEX(GearDB_WSACC,$B$6),0)))+IF(Build!$B$18="(keep equipped)",0,IF($C$6>0,Build!$D$18*INDEX(AugDB_WSACC,$C$6),0)+IF(Build!$E$18="WSACC",Build!$F$18,0)+IF(Build!$G$18="WSACC",Build!$H$18,0)) | AC6: =IF(Build!$B$18="(keep equipped)",EquipBase!$AA$6,IF(OR(Build!$B$18="(none)",Build!$B$18=""),0,IFERROR(INDEX(GearDB_WSDMG_225,$B$6),0)))+IF(Build!$B$18="(keep equipped)",0,IF($C$6>0,Build!$D$18*INDEX(AugDB_WSDMG_225,$C$6),0)+IF(Build!$E$18="WSDMG_225",Build!$F$18,0)+IF(Build!$G$18="WSDMG_225",Build!$H$18,0))
A7: legs | B7: =IFERROR(MATCH(Build!$B$19,GearDB_names,0),0) | C7: =IFERROR(MATCH(Build!$C$19,AugDB_labels,0),0) | D7: =IF(Build!$B$19="(keep equipped)",EquipBase!$B$7,IF(OR(Build!$B$19="(none)",Build!$B$19=""),0,IFERROR(INDEX(GearDB_STR,$B$7),0)))+IF(Build!$B$19="(keep equipped)",0,IF($C$7>0,Build!$D$19*INDEX(AugDB_STR,$C$7),0)+IF(Build!$E$19="STR",Build!$F$19,0)+IF(Build!$G$19="STR",Build!$H$19,0)) | E7: =IF(Build!$B$19="(keep equipped)",EquipBase!$C$7,IF(OR(Build!$B$19="(none)",Build!$B$19=""),0,IFERROR(INDEX(GearDB_DEX,$B$7),0)))+IF(Build!$B$19="(keep equipped)",0,IF($C$7>0,Build!$D$19*INDEX(AugDB_DEX,$C$7),0)+IF(Build!$E$19="DEX",Build!$F$19,0)+IF(Build!$G$19="DEX",Build!$H$19,0)) | F7: =IF(Build!$B$19="(keep equipped)",EquipBase!$D$7,IF(OR(Build!$B$19="(none)",Build!$B$19=""),0,IFERROR(INDEX(GearDB_VIT,$B$7),0)))+IF(Build!$B$19="(keep equipped)",0,IF($C$7>0,Build!$D$19*INDEX(AugDB_VIT,$C$7),0)+IF(Build!$E$19="VIT",Build!$F$19,0)+IF(Build!$G$19="VIT",Build!$H$19,0)) | G7: =IF(Build!$B$19="(keep equipped)",EquipBase!$E$7,IF(OR(Build!$B$19="(none)",Build!$B$19=""),0,IFERROR(INDEX(GearDB_AGI,$B$7),0)))+IF(Build!$B$19="(keep equipped)",0,IF($C$7>0,Build!$D$19*INDEX(AugDB_AGI,$C$7),0)+IF(Build!$E$19="AGI",Build!$F$19,0)+IF(Build!$G$19="AGI",Build!$H$19,0)) | H7: =IF(Build!$B$19="(keep equipped)",EquipBase!$F$7,IF(OR(Build!$B$19="(none)",Build!$B$19=""),0,IFERROR(INDEX(GearDB_INT,$B$7),0)))+IF(Build!$B$19="(keep equipped)",0,IF($C$7>0,Build!$D$19*INDEX(AugDB_INT,$C$7),0)+IF(Build!$E$19="INT",Build!$F$19,0)+IF(Build!$G$19="INT",Build!$H$19,0)) | I7: =IF(Build!$B$19="(keep equipped)",EquipBase!$G$7,IF(OR(Build!$B$19="(none)",Build!$B$19=""),0,IFERROR(INDEX(GearDB_MND,$B$7),0)))+IF(Build!$B$19="(keep equipped)",0,IF($C$7>0,Build!$D$19*INDEX(AugDB_MND,$C$7),0)+IF(Build!$E$19="MND",Build!$F$19,0)+IF(Build!$G$19="MND",Build!$H$19,0)) | J7: =IF(Build!$B$19="(keep equipped)",EquipBase!$H$7,IF(OR(Build!$B$19="(none)",Build!$B$19=""),0,IFERROR(INDEX(GearDB_CHR,$B$7),0)))+IF(Build!$B$19="(keep equipped)",0,IF($C$7>0,Build!$D$19*INDEX(AugDB_CHR,$C$7),0)+IF(Build!$E$19="CHR",Build!$F$19,0)+IF(Build!$G$19="CHR",Build!$H$19,0)) | K7: =IF(Build!$B$19="(keep equipped)",EquipBase!$I$7,IF(OR(Build!$B$19="(none)",Build!$B$19=""),0,IFERROR(INDEX(GearDB_ATT,$B$7),0)))+IF(Build!$B$19="(keep equipped)",0,IF($C$7>0,Build!$D$19*INDEX(AugDB_ATT,$C$7),0)+IF(Build!$E$19="ATT",Build!$F$19,0)+IF(Build!$G$19="ATT",Build!$H$19,0)) | L7: =IF(Build!$B$19="(keep equipped)",EquipBase!$J$7,IF(OR(Build!$B$19="(none)",Build!$B$19=""),0,IFERROR(INDEX(GearDB_ATTP,$B$7),0)))+IF(Build!$B$19="(keep equipped)",0,IF($C$7>0,Build!$D$19*INDEX(AugDB_ATTP,$C$7),0)+IF(Build!$E$19="ATTP",Build!$F$19,0)+IF(Build!$G$19="ATTP",Build!$H$19,0)) | M7: =IF(Build!$B$19="(keep equipped)",EquipBase!$K$7,IF(OR(Build!$B$19="(none)",Build!$B$19=""),0,IFERROR(INDEX(GearDB_ACC,$B$7),0)))+IF(Build!$B$19="(keep equipped)",0,IF($C$7>0,Build!$D$19*INDEX(AugDB_ACC,$C$7),0)+IF(Build!$E$19="ACC",Build!$F$19,0)+IF(Build!$G$19="ACC",Build!$H$19,0)) | N7: =IF(Build!$B$19="(keep equipped)",EquipBase!$L$7,IF(OR(Build!$B$19="(none)",Build!$B$19=""),0,IFERROR(INDEX(GearDB_CRITHITRATE,$B$7),0)))+IF(Build!$B$19="(keep equipped)",0,IF($C$7>0,Build!$D$19*INDEX(AugDB_CRITHITRATE,$C$7),0)+IF(Build!$E$19="CRITHITRATE",Build!$F$19,0)+IF(Build!$G$19="CRITHITRATE",Build!$H$19,0)) | O7: =IF(Build!$B$19="(keep equipped)",EquipBase!$M$7,IF(OR(Build!$B$19="(none)",Build!$B$19=""),0,IFERROR(INDEX(GearDB_CRIT_DMG_INCREASE,$B$7),0)))+IF(Build!$B$19="(keep equipped)",0,IF($C$7>0,Build!$D$19*INDEX(AugDB_CRIT_DMG_INCREASE,$C$7),0)+IF(Build!$E$19="CRIT_DMG_INCREASE",Build!$F$19,0)+IF(Build!$G$19="CRIT_DMG_INCREASE",Build!$H$19,0)) | P7: =IF(Build!$B$19="(keep equipped)",EquipBase!$N$7,IF(OR(Build!$B$19="(none)",Build!$B$19=""),0,IFERROR(INDEX(GearDB_DOUBLE_ATTACK,$B$7),0)))+IF(Build!$B$19="(keep equipped)",0,IF($C$7>0,Build!$D$19*INDEX(AugDB_DOUBLE_ATTACK,$C$7),0)+IF(Build!$E$19="DOUBLE_ATTACK",Build!$F$19,0)+IF(Build!$G$19="DOUBLE_ATTACK",Build!$H$19,0)) | Q7: =IF(Build!$B$19="(keep equipped)",EquipBase!$O$7,IF(OR(Build!$B$19="(none)",Build!$B$19=""),0,IFERROR(INDEX(GearDB_TRIPLE_ATTACK,$B$7),0)))+IF(Build!$B$19="(keep equipped)",0,IF($C$7>0,Build!$D$19*INDEX(AugDB_TRIPLE_ATTACK,$C$7),0)+IF(Build!$E$19="TRIPLE_ATTACK",Build!$F$19,0)+IF(Build!$G$19="TRIPLE_ATTACK",Build!$H$19,0)) | R7: =IF(Build!$B$19="(keep equipped)",EquipBase!$P$7,IF(OR(Build!$B$19="(none)",Build!$B$19=""),0,IFERROR(INDEX(GearDB_QUAD_ATTACK,$B$7),0)))+IF(Build!$B$19="(keep equipped)",0,IF($C$7>0,Build!$D$19*INDEX(AugDB_QUAD_ATTACK,$C$7),0)+IF(Build!$E$19="QUAD_ATTACK",Build!$F$19,0)+IF(Build!$G$19="QUAD_ATTACK",Build!$H$19,0)) | S7: =IF(Build!$B$19="(keep equipped)",EquipBase!$Q$7,IF(OR(Build!$B$19="(none)",Build!$B$19=""),0,IFERROR(INDEX(GearDB_HASTE_GEAR,$B$7),0)))+IF(Build!$B$19="(keep equipped)",0,IF($C$7>0,Build!$D$19*INDEX(AugDB_HASTE_GEAR,$C$7),0)+IF(Build!$E$19="HASTE_GEAR",Build!$F$19,0)+IF(Build!$G$19="HASTE_GEAR",Build!$H$19,0)) | T7: =IF(Build!$B$19="(keep equipped)",EquipBase!$R$7,IF(OR(Build!$B$19="(none)",Build!$B$19=""),0,IFERROR(INDEX(GearDB_HASTE_MAGIC,$B$7),0)))+IF(Build!$B$19="(keep equipped)",0,IF($C$7>0,Build!$D$19*INDEX(AugDB_HASTE_MAGIC,$C$7),0)+IF(Build!$E$19="HASTE_MAGIC",Build!$F$19,0)+IF(Build!$G$19="HASTE_MAGIC",Build!$H$19,0)) | U7: =IF(Build!$B$19="(keep equipped)",EquipBase!$S$7,IF(OR(Build!$B$19="(none)",Build!$B$19=""),0,IFERROR(INDEX(GearDB_HASTE_ABILITY,$B$7),0)))+IF(Build!$B$19="(keep equipped)",0,IF($C$7>0,Build!$D$19*INDEX(AugDB_HASTE_ABILITY,$C$7),0)+IF(Build!$E$19="HASTE_ABILITY",Build!$F$19,0)+IF(Build!$G$19="HASTE_ABILITY",Build!$H$19,0)) | V7: =IF(Build!$B$19="(keep equipped)",EquipBase!$T$7,IF(OR(Build!$B$19="(none)",Build!$B$19=""),0,IFERROR(INDEX(GearDB_DUAL_WIELD,$B$7),0)))+IF(Build!$B$19="(keep equipped)",0,IF($C$7>0,Build!$D$19*INDEX(AugDB_DUAL_WIELD,$C$7),0)+IF(Build!$E$19="DUAL_WIELD",Build!$F$19,0)+IF(Build!$G$19="DUAL_WIELD",Build!$H$19,0)) | W7: =IF(Build!$B$19="(keep equipped)",EquipBase!$U$7,IF(OR(Build!$B$19="(none)",Build!$B$19=""),0,IFERROR(INDEX(GearDB_STORETP,$B$7),0)))+IF(Build!$B$19="(keep equipped)",0,IF($C$7>0,Build!$D$19*INDEX(AugDB_STORETP,$C$7),0)+IF(Build!$E$19="STORETP",Build!$F$19,0)+IF(Build!$G$19="STORETP",Build!$H$19,0)) | X7: =IF(Build!$B$19="(keep equipped)",EquipBase!$V$7,IF(OR(Build!$B$19="(none)",Build!$B$19=""),0,IFERROR(INDEX(GearDB_TP_BONUS,$B$7),0)))+IF(Build!$B$19="(keep equipped)",0,IF($C$7>0,Build!$D$19*INDEX(AugDB_TP_BONUS,$C$7),0)+IF(Build!$E$19="TP_BONUS",Build!$F$19,0)+IF(Build!$G$19="TP_BONUS",Build!$H$19,0)) | Y7: =IF(Build!$B$19="(keep equipped)",EquipBase!$W$7,IF(OR(Build!$B$19="(none)",Build!$B$19=""),0,IFERROR(INDEX(GearDB_ALL_WSDMG_ALL_HITS,$B$7),0)))+IF(Build!$B$19="(keep equipped)",0,IF($C$7>0,Build!$D$19*INDEX(AugDB_ALL_WSDMG_ALL_HITS,$C$7),0)+IF(Build!$E$19="ALL_WSDMG_ALL_HITS",Build!$F$19,0)+IF(Build!$G$19="ALL_WSDMG_ALL_HITS",Build!$H$19,0)) | Z7: =IF(Build!$B$19="(keep equipped)",EquipBase!$X$7,IF(OR(Build!$B$19="(none)",Build!$B$19=""),0,IFERROR(INDEX(GearDB_ALL_WSDMG_FIRST_HIT,$B$7),0)))+IF(Build!$B$19="(keep equipped)",0,IF($C$7>0,Build!$D$19*INDEX(AugDB_ALL_WSDMG_FIRST_HIT,$C$7),0)+IF(Build!$E$19="ALL_WSDMG_FIRST_HIT",Build!$F$19,0)+IF(Build!$G$19="ALL_WSDMG_FIRST_HIT",Build!$H$19,0)) | AA7: =IF(Build!$B$19="(keep equipped)",EquipBase!$Y$7,IF(OR(Build!$B$19="(none)",Build!$B$19=""),0,IFERROR(INDEX(GearDB_ANY_FTP_BONUS,$B$7),0)))+IF(Build!$B$19="(keep equipped)",0,IF($C$7>0,Build!$D$19*INDEX(AugDB_ANY_FTP_BONUS,$C$7),0)+IF(Build!$E$19="ANY_FTP_BONUS",Build!$F$19,0)+IF(Build!$G$19="ANY_FTP_BONUS",Build!$H$19,0)) | AB7: =IF(Build!$B$19="(keep equipped)",EquipBase!$Z$7,IF(OR(Build!$B$19="(none)",Build!$B$19=""),0,IFERROR(INDEX(GearDB_WSACC,$B$7),0)))+IF(Build!$B$19="(keep equipped)",0,IF($C$7>0,Build!$D$19*INDEX(AugDB_WSACC,$C$7),0)+IF(Build!$E$19="WSACC",Build!$F$19,0)+IF(Build!$G$19="WSACC",Build!$H$19,0)) | AC7: =IF(Build!$B$19="(keep equipped)",EquipBase!$AA$7,IF(OR(Build!$B$19="(none)",Build!$B$19=""),0,IFERROR(INDEX(GearDB_WSDMG_225,$B$7),0)))+IF(Build!$B$19="(keep equipped)",0,IF($C$7>0,Build!$D$19*INDEX(AugDB_WSDMG_225,$C$7),0)+IF(Build!$E$19="WSDMG_225",Build!$F$19,0)+IF(Build!$G$19="WSDMG_225",Build!$H$19,0))
